<robot name="go2">  <link name="base_link"> <inertial> <origin rpy="0 0 0" xyz="0.021112 0 -0.005366" /> <mass value="6.921" /> <inertia ixx="0.02448" ixy="0.00012166" ixz="0.0014849" iyy="0.098077" iyz="-3.12E-05" izz="0.107" /> </inertial> <visual> <origin rpy="0 0 0" xyz="0 0 0" /> <geometry> <mesh filename="assets/go2_description/glb/base.glb" scale="1 1 1" /> </geometry> <material name=""> <color rgba="1 1 1 1" /> </material> </visual> <collision> <origin rpy="0 0 0" xyz="0 0 0" /> <geometry> <box size="0.3762 0.0935 0.114" /> </geometry> </collision> </link> <link name="odom"> </link> <link name="Head_upper"> <inertial> <origin rpy="0 0 0" xyz="0 0 0" /> <mass value="0.001" /> <inertia ixx="9.6e-06" ixy="0" ixz="0" iyy="9.6e-06" iyz="0" izz="9.6e-06" /> </inertial> <collision> <origin rpy="0 0 0" xyz="0 0 0" /> <geometry> <cylinder length="0.09" radius="0.05" /> </geometry> </collision> </link> <link name="Head_lower"> <inertial> <origin rpy="0 0 0" xyz="0 0 0" /> <mass value="0.001" /> <inertia ixx="9.6e-06" ixy="0" ixz="0" iyy="9.6e-06" iyz="0" izz="9.6e-06" /> </inertial> <collision> <origin rpy="0 0 0" xyz="0 0 0" /> <geometry> <sphere radius="0.047" /> </geometry> </collision> </link> <link name="imu"> <inertial> <origin rpy="0 0 0" xyz="0 0 0" /> <mass value="0" /> <inertia ixx="0" ixy="0" ixz="0" iyy="0" iyz="0" izz="0" /> </inertial> </link> <link name="radar"> <inertial> <origin rpy="0 0 0" xyz="0 0 0" /> <mass value="0" /> <inertia ixx="0" ixy="0" ixz="0" iyy="0" iyz="0" izz="0" /> </inertial> </link> <joint name="odom_joint" type="fixed"> <origin rpy="0 0 0" xyz="0 0 0" /> <parent link="odom" /> <child link="base_link" /> </joint> <joint dont_collapse="true" name="Head_upper_joint" type="fixed"> <origin rpy="0 0 0" xyz="0.285 0 0.01" /> <parent link="base_link" /> <child link="Head_upper" /> <axis xyz="0 0 0" /> </joint> <joint dont_collapse="true" name="Head_lower_joint" type="fixed"> <origin rpy="0 0 0" xyz="0.008 0 -0.07" /> <parent link="Head_upper" /> <child link="Head_lower" /> <axis xyz="0 0 0" /> </joint> <joint name="imu_joint" type="fixed"> <origin rpy="0 0 0" xyz="-0.02557 0 0.04232" /> <parent link="base_link" /> <child link="imu" /> <axis xyz="0 0 0" /> </joint> <joint name="radar_joint" type="fixed"> <origin rpy="0 2.8782 0" xyz="0.28945 0 -0.046825" /> <parent link="base_link" /> <child link="radar" /> <axis xyz="0 0 0" /> </joint>  <link name="LF_hip"> <inertial> <origin rpy="0 0 0" xyz="-0.0054 0.00194 -0.000105" /> <mass value="0.678" /> <inertia ixx="0.00048" ixy="-3.01E-06" ixz="1.11E-06" iyy="0.000884" iyz="-1.42E-06" izz="0.000596" /> </inertial> <visual> <origin rpy="0 0 0" xyz="0 0 0" /> <geometry> <mesh filename="assets/go2_description/glb/hip.glb" scale="1 1 1" /> </geometry> <material name=""> <color rgba="1 1 1 1" /> </material> </visual> <collision> <origin rpy="1.5707963267948966 0 0" xyz="0 0.08 0" /> <geometry> <cylinder length="0.04" radius="0.046" /> </geometry> </collision> </link> <joint name="LF_hip_joint" type="revolute"> <origin rpy="0 0 0" xyz="0.1934 0.0465 0" /> <parent link="base_link" /> <child link="LF_hip" /> <axis xyz="1 0 0" /> <limit effort="23.7" lower="-1.0472" upper="1.0472" velocity="30.1" /> </joint> <link name="LF_thigh"> <inertial> <origin rpy="0 0 0" xyz="-0.00374 -0.0223 -0.0327" /> <mass value="1.152" /> <inertia ixx="0.00584" ixy="8.72E-05" ixz="-0.000289" iyy="0.0058" iyz="0.000808" izz="0.00103" /> </inertial> <visual> <origin rpy="0 0 0" xyz="0 0 0" /> <geometry> <mesh filename="assets/go2_description/glb/thigh.glb" scale="1 1 1" /> </geometry> <material name=""> <color rgba="1 1 1 1" /> </material> </visual> <collision> <origin rpy="0 1.5707963267948966 0" xyz="0 0 -0.1065" /> <geometry> <box size="0.213 0.0245 0.034" /> </geometry> </collision> </link> <joint name="LF_upper_leg_joint" type="revolute"> <origin rpy="0 0 0" xyz="0 0.0955 0" /> <parent link="LF_hip" /> <child link="LF_thigh" /> <axis xyz="0 1 0" /> <limit effort="23.7" lower="-0.5236" upper="4.5379" velocity="30.1" /> </joint> <link name="LF_calf"> <inertial> <origin rpy="0 0 0" xyz="0.00548 -0.000975 -0.115" /> <mass value="0.154" /> <inertia ixx="0.00108" ixy="3.4E-07" ixz="1.72E-05" iyy="0.0011" iyz="8.28E-06" izz="3.29E-05" /> </inertial> <visual> <origin rpy="0 0 0" xyz="0 0 0" /> <geometry> <mesh filename="assets/go2_description/glb/calf.glb" scale="1 1 1" /> </geometry> <material name=""> <color rgba="1 1 1 1" /> </material> </visual> <collision> <origin rpy="0 -0.21 0" xyz="0.008 0 -0.06" /> <geometry> <cylinder length="0.12" radius="0.012" /> </geometry> </collision> </link> <joint name="LF_lower_leg_joint" type="revolute"> <origin rpy="0 0 0" xyz="0 0 -0.213" /> <parent link="LF_thigh" /> <child link="LF_calf" /> <axis xyz="0 1 0" /> <limit effort="45.43" lower="-2.7227" upper="-0.83776" velocity="15.70" /> </joint> <link name="LF_foot"> <inertial> <origin rpy="0 0 0" xyz="0 0 0" /> <mass value="0.04" /> <inertia ixx="9.6e-06" ixy="0" ixz="0" iyy="9.6e-06" iyz="0" izz="9.6e-06" /> </inertial> <visual> <origin rpy="0 0 0" xyz="0 0 0" /> <geometry> <mesh filename="assets/go2_description/glb/foot.glb" scale="1 1 1" /> </geometry> <material name=""> <color rgba="1 1 1 1" /> </material> </visual> <collision> <origin rpy="0 0 0" xyz="-0.002 0 0" /> <geometry> <sphere radius="0.022" /> </geometry> </collision> </link> <joint dont_collapse="true" name="LF_foot_joint" type="fixed"> <origin rpy="0 0 0" xyz="0 0 -0.213" /> <parent link="LF_calf" /> <child link="LF_foot" /> <axis xyz="0 0 0" /> </joint> <link name="RF_hip"> <inertial> <origin rpy="0 0 0" xyz="-0.0054 -0.00194 -0.000105" /> <mass value="0.678" /> <inertia ixx="0.00048" ixy="-3.01E-06" ixz="1.11E-06" iyy="0.000884" iyz="-1.42E-06" izz="0.000596" /> </inertial> <visual> <origin rpy="0 0 0" xyz="0 0 0" /> <geometry> <mesh filename="assets/go2_description/glb/hip.glb" scale="1 1 1" /> </geometry> <material name=""> <color rgba="1 1 1 1" /> </material> </visual> <collision> <origin rpy="1.5707963267948966 0 0" xyz="0 0.08 0" /> <geometry> <cylinder length="0.04" radius="0.046" /> </geometry> </collision> </link> <joint name="RF_hip_joint" type="revolute"> <origin rpy="0 0 0" xyz="0.1934 -0.0465 0" /> <parent link="base_link" /> <child link="RF_hip" /> <axis xyz="1 0 0" /> <limit effort="23.7" lower="-1.0472" upper="1.0472" velocity="30.1" /> </joint> <link name="RF_thigh"> <inertial> <origin rpy="0 0 0" xyz="-0.00374 -0.0223 -0.0327" /> <mass value="1.152" /> <inertia ixx="0.00584" ixy="8.72E-05" ixz="-0.000289" iyy="0.0058" iyz="0.000808" izz="0.00103" /> </inertial> <visual> <origin rpy="0 0 0" xyz="0 0 0" /> <geometry> <mesh filename="assets/go2_description/glb/thigh_mirror.glb" scale="1 1 1" /> </geometry> <material name=""> <color rgba="1 1 1 1" /> </material> </visual> <collision> <origin rpy="0 1.5707963267948966 0" xyz="0 0 -0.1065" /> <geometry> <box size="0.213 0.0245 0.034" /> </geometry> </collision> </link> <joint name="RF_upper_leg_joint" type="revolute"> <origin rpy="0 0 0" xyz="0 -0.0955 0" /> <parent link="RF_hip" /> <child link="RF_thigh" /> <axis xyz="0 1 0" /> <limit effort="23.7" lower="-0.5236" upper="4.5379" velocity="30.1" /> </joint> <link name="RF_calf"> <inertial> <origin rpy="0 0 0" xyz="0.00548 -0.000975 -0.115" /> <mass value="0.154" /> <inertia ixx="0.00108" ixy="3.4E-07" ixz="1.72E-05" iyy="0.0011" iyz="8.28E-06" izz="3.29E-05" /> </inertial> <visual> <origin rpy="0 0 0" xyz="0 0 0" /> <geometry> <mesh filename="assets/go2_description/glb/calf_mirror.glb" scale="1 1 1" /> </geometry> <material name=""> <color rgba="1 1 1 1" /> </material> </visual> <collision> <origin rpy="0 -0.21 0" xyz="0.008 0 -0.06" /> <geometry> <cylinder length="0.12" radius="0.012" /> </geometry> </collision> </link> <joint name="RF_lower_leg_joint" type="revolute"> <origin rpy="0 0 0" xyz="0 0 -0.213" /> <parent link="RF_thigh" /> <child link="RF_calf" /> <axis xyz="0 1 0" /> <limit effort="45.43" lower="-2.7227" upper="-0.83776" velocity="15.70" /> </joint> <link name="RF_foot"> <inertial> <origin rpy="0 0 0" xyz="0 0 0" /> <mass value="0.04" /> <inertia ixx="9.6e-06" ixy="0" ixz="0" iyy="9.6e-06" iyz="0" izz="9.6e-06" /> </inertial> <visual> <origin rpy="0 0 0" xyz="0 0 0" /> <geometry> <mesh filename="assets/go2_description/glb/foot.glb" scale="1 1 1" /> </geometry> <material name=""> <color rgba="1 1 1 1" /> </material> </visual> <collision> <origin rpy="0 0 0" xyz="-0.002 0 0" /> <geometry> <sphere radius="0.022" /> </geometry> </collision> </link> <joint dont_collapse="true" name="RF_foot_joint" type="fixed"> <origin rpy="0 0 0" xyz="0 0 -0.213" /> <parent link="RF_calf" /> <child link="RF_foot" /> <axis xyz="0 0 0" /> </joint> <link name="LR_hip"> <inertial> <origin rpy="0 0 0" xyz="0.0054 0.00194 -0.000105" /> <mass value="0.678" /> <inertia ixx="0.00048" ixy="-3.01E-06" ixz="1.11E-06" iyy="0.000884" iyz="-1.42E-06" izz="0.000596" /> </inertial> <visual> <origin rpy="0 0 0" xyz="0 0 0" /> <geometry> <mesh filename="assets/go2_description/glb/hip.glb" scale="1 1 1" /> </geometry> <material name=""> <color rgba="1 1 1 1" /> </material> </visual> <collision> <origin rpy="1.5707963267948966 0 0" xyz="0 0.08 0" /> <geometry> <cylinder length="0.04" radius="0.046" /> </geometry> </collision> </link> <joint name="LR_hip_joint" type="revolute"> <origin rpy="0 0 0" xyz="-0.1934 0.0465 0" /> <parent link="base_link" /> <child link="LR_hip" /> <axis xyz="1 0 0" /> <limit effort="23.7" lower="-1.0472" upper="1.0472" velocity="30.1" /> </joint> <link name="LR_thigh"> <inertial> <origin rpy="0 0 0" xyz="-0.00374 -0.0223 -0.0327" /> <mass value="1.152" /> <inertia ixx="0.00584" ixy="8.72E-05" ixz="-0.000289" iyy="0.0058" iyz="0.000808" izz="0.00103" /> </inertial> <visual> <origin rpy="0 0 0" xyz="0 0 0" /> <geometry> <mesh filename="assets/go2_description/glb/thigh.glb" scale="1 1 1" /> </geometry> <material name=""> <color rgba="1 1 1 1" /> </material> </visual> <collision> <origin rpy="0 1.5707963267948966 0" xyz="0 0 -0.1065" /> <geometry> <box size="0.213 0.0245 0.034" /> </geometry> </collision> </link> <joint name="LR_upper_leg_joint" type="revolute"> <origin rpy="0 0 0" xyz="0 0.0955 0" /> <parent link="LR_hip" /> <child link="LR_thigh" /> <axis xyz="0 1 0" /> <limit effort="23.7" lower="-0.5236" upper="4.5379" velocity="30.1" /> </joint> <link name="LR_calf"> <inertial> <origin rpy="0 0 0" xyz="0.00548 -0.000975 -0.115" /> <mass value="0.154" /> <inertia ixx="0.00108" ixy="3.4E-07" ixz="1.72E-05" iyy="0.0011" iyz="8.28E-06" izz="3.29E-05" /> </inertial> <visual> <origin rpy="0 0 0" xyz="0 0 0" /> <geometry> <mesh filename="assets/go2_description/glb/calf.glb" scale="1 1 1" /> </geometry> <material name=""> <color rgba="1 1 1 1" /> </material> </visual> <collision> <origin rpy="0 -0.21 0" xyz="0.008 0 -0.06" /> <geometry> <cylinder length="0.12" radius="0.012" /> </geometry> </collision> </link> <joint name="LR_lower_leg_joint" type="revolute"> <origin rpy="0 0 0" xyz="0 0 -0.213" /> <parent link="LR_thigh" /> <child link="LR_calf" /> <axis xyz="0 1 0" /> <limit effort="45.43" lower="-2.7227" upper="-0.83776" velocity="15.70" /> </joint> <link name="LR_foot"> <inertial> <origin rpy="0 0 0" xyz="0 0 0" /> <mass value="0.04" /> <inertia ixx="9.6e-06" ixy="0" ixz="0" iyy="9.6e-06" iyz="0" izz="9.6e-06" /> </inertial> <visual> <origin rpy="0 0 0" xyz="0 0 0" /> <geometry> <mesh filename="assets/go2_description/glb/foot.glb" scale="1 1 1" /> </geometry> <material name=""> <color rgba="1 1 1 1" /> </material> </visual> <collision> <origin rpy="0 0 0" xyz="-0.002 0 0" /> <geometry> <sphere radius="0.022" /> </geometry> </collision> </link> <joint dont_collapse="true" name="LR_foot_joint" type="fixed"> <origin rpy="0 0 0" xyz="0 0 -0.213" /> <parent link="LR_calf" /> <child link="LR_foot" /> <axis xyz="0 0 0" /> </joint> <link name="RR_hip"> <inertial> <origin rpy="0 0 0" xyz="0.0054 -0.00194 -0.000105" /> <mass value="0.678" /> <inertia ixx="0.00048" ixy="-3.01E-06" ixz="1.11E-06" iyy="0.000884" iyz="-1.42E-06" izz="0.000596" /> </inertial> <visual> <origin rpy="0 0 0" xyz="0 0 0" /> <geometry> <mesh filename="assets/go2_description/glb/hip.glb" scale="1 1 1" /> </geometry> <material name=""> <color rgba="1 1 1 1" /> </material> </visual> <collision> <origin rpy="1.5707963267948966 0 0" xyz="0 0.08 0" /> <geometry> <cylinder length="0.04" radius="0.046" /> </geometry> </collision> </link> <joint name="RR_hip_joint" type="revolute"> <origin rpy="0 0 0" xyz="-0.1934 -0.0465 0" /> <parent link="base_link" /> <child link="RR_hip" /> <axis xyz="1 0 0" /> <limit effort="23.7" lower="-1.0472" upper="1.0472" velocity="30.1" /> </joint> <link name="RR_thigh"> <inertial> <origin rpy="0 0 0" xyz="-0.00374 -0.0223 -0.0327" /> <mass value="1.152" /> <inertia ixx="0.00584" ixy="8.72E-05" ixz="-0.000289" iyy="0.0058" iyz="0.000808" izz="0.00103" /> </inertial> <visual> <origin rpy="0 0 0" xyz="0 0 0" /> <geometry> <mesh filename="assets/go2_description/glb/thigh_mirror.glb" scale="1 1 1" /> </geometry> <material name=""> <color rgba="1 1 1 1" /> </material> </visual> <collision> <origin rpy="0 1.5707963267948966 0" xyz="0 0 -0.1065" /> <geometry> <box size="0.213 0.0245 0.034" /> </geometry> </collision> </link> <joint name="RR_upper_leg_joint" type="revolute"> <origin rpy="0 0 0" xyz="0 -0.0955 0" /> <parent link="RR_hip" /> <child link="RR_thigh" /> <axis xyz="0 1 0" /> <limit effort="23.7" lower="-0.5236" upper="4.5379" velocity="30.1" /> </joint> <link name="RR_calf"> <inertial> <origin rpy="0 0 0" xyz="0.00548 -0.000975 -0.115" /> <mass value="0.154" /> <inertia ixx="0.00108" ixy="3.4E-07" ixz="1.72E-05" iyy="0.0011" iyz="8.28E-06" izz="3.29E-05" /> </inertial> <visual> <origin rpy="0 0 0" xyz="0 0 0" /> <geometry> <mesh filename="assets/go2_description/glb/calf_mirror.glb" scale="1 1 1" /> </geometry> <material name=""> <color rgba="1 1 1 1" /> </material> </visual> <collision> <origin rpy="0 -0.21 0" xyz="0.008 0 -0.06" /> <geometry> <cylinder length="0.12" radius="0.012" /> </geometry> </collision> </link> <joint name="RR_lower_leg_joint" type="revolute"> <origin rpy="0 0 0" xyz="0 0 -0.213" /> <parent link="RR_thigh" /> <child link="RR_calf" /> <axis xyz="0 1 0" /> <limit effort="45.43" lower="-2.7227" upper="-0.83776" velocity="15.70" /> </joint> <link name="RR_foot"> <inertial> <origin rpy="0 0 0" xyz="0 0 0" /> <mass value="0.04" /> <inertia ixx="9.6e-06" ixy="0" ixz="0" iyy="9.6e-06" iyz="0" izz="9.6e-06" /> </inertial> <visual> <origin rpy="0 0 0" xyz="0 0 0" /> <geometry> <mesh filename="assets/go2_description/glb/foot.glb" scale="1 1 1" /> </geometry> <material name=""> <color rgba="1 1 1 1" /> </material> </visual> <collision> <origin rpy="0 0 0" xyz="-0.002 0 0" /> <geometry> <sphere radius="0.022" /> </geometry> </collision> </link> <joint dont_collapse="true" name="RR_foot_joint" type="fixed"> <origin rpy="0 0 0" xyz="0 0 -0.213" /> <parent link="RR_calf" /> <child link="RR_foot" /> <axis xyz="0 0 0" /> </joint> </robot>